python: can't open file '/code/manage.py': [Errno 2] No such file or directory
python: can't open file '/code/manage.py': [Errno 2] No such file or directory
python: can't open file '/code/manage.py': [Errno 2] No such file or directory
python: can't open file '/code/manage.py': [Errno 2] No such file or directory
python: can't open file '/code/manage.py': [Errno 2] No such file or directory
python: can't open file '/code/manage.py': [Errno 2] No such file or directory
python: can't open file '/code/manage.py': [Errno 2] No such file or directory
python: can't open file '/code/manage.py': [Errno 2] No such file or directory
python: can't open file '/code/manage.py': [Errno 2] No such file or directory
python: can't open file '/code/manage.py': [Errno 2] No such file or directory
python: can't open file '/code/manage.py': [Errno 2] No such file or directory
python: can't open file '/code/manage.py': [Errno 2] No such file or directory
python: can't open file '/code/manage.py': [Errno 2] No such file or directory
python: can't open file '/code/manage.py': [Errno 2] No such file or directory
python: can't open file '/code/manage.py': [Errno 2] No such file or directory
python: can't open file '/code/manage.py': [Errno 2] No such file or directory
python: can't open file '/code/manage.py': [Errno 2] No such file or directory
python: can't open file '/code/manage.py': [Errno 2] No such file or directory
python: can't open file '/code/manage.py': [Errno 2] No such file or directory
python: can't open file '/code/manage.py': [Errno 2] No such file or directory
python: can't open file '/code/manage.py': [Errno 2] No such file or directory
python: can't open file '/code/manage.py': [Errno 2] No such file or directory
python: can't open file '/code/manage.py': [Errno 2] No such file or directory
python: can't open file '/code/manage.py': [Errno 2] No such file or directory
python: can't open file '/code/manage.py': [Errno 2] No such file or directory
python: can't open file '/code/manage.py': [Errno 2] No such file or directory
python: can't open file '/code/manage.py': [Errno 2] No such file or directory
python: can't open file '/code/manage.py': [Errno 2] No such file or directory
Watching for file changes with StatReloader
Invalid HTTP_HOST header: 'cactuar.commemabite.fr:4242'. You may need to add 'cactuar.commemabite.fr' to ALLOWED_HOSTS.
Bad Request: /
[03/Feb/2022 13:21:42] "GET / HTTP/1.1" 400 66694
Invalid HTTP_HOST header: 'cactuar.commemabite.fr:4242'. You may need to add 'cactuar.commemabite.fr' to ALLOWED_HOSTS.
Bad Request: /favicon.ico
[03/Feb/2022 13:21:44] "GET /favicon.ico HTTP/1.1" 400 66771
Traceback (most recent call last):
  File "/code/manage.py", line 22, in <module>
    main()
  File "/code/manage.py", line 18, in main
    execute_from_command_line(sys.argv)
  File "/usr/local/lib/python3.10/site-packages/django/core/management/__init__.py", line 425, in execute_from_command_line
    utility.execute()
  File "/usr/local/lib/python3.10/site-packages/django/core/management/__init__.py", line 369, in execute
    settings.INSTALLED_APPS
  File "/usr/local/lib/python3.10/site-packages/django/conf/__init__.py", line 84, in __getattr__
    self._setup(name)
  File "/usr/local/lib/python3.10/site-packages/django/conf/__init__.py", line 71, in _setup
    self._wrapped = Settings(settings_module)
  File "/usr/local/lib/python3.10/site-packages/django/conf/__init__.py", line 179, in __init__
    mod = importlib.import_module(self.SETTINGS_MODULE)
  File "/usr/local/lib/python3.10/importlib/__init__.py", line 126, in import_module
    return _bootstrap._gcd_import(name[level:], package, level)
  File "<frozen importlib._bootstrap>", line 1050, in _gcd_import
  File "<frozen importlib._bootstrap>", line 1027, in _find_and_load
  File "<frozen importlib._bootstrap>", line 1006, in _find_and_load_unlocked
  File "<frozen importlib._bootstrap>", line 688, in _load_unlocked
  File "<frozen importlib._bootstrap_external>", line 879, in exec_module
  File "<frozen importlib._bootstrap_external>", line 1017, in get_code
  File "<frozen importlib._bootstrap_external>", line 947, in source_to_code
  File "<frozen importlib._bootstrap>", line 241, in _call_with_frames_removed
  File "/code/geospace/settings.py", line 28
    ALLOWED_HOSTS = [*]
                      ^
SyntaxError: invalid syntax
Traceback (most recent call last):
  File "/code/manage.py", line 22, in <module>
    main()
  File "/code/manage.py", line 18, in main
    execute_from_command_line(sys.argv)
  File "/usr/local/lib/python3.10/site-packages/django/core/management/__init__.py", line 425, in execute_from_command_line
    utility.execute()
  File "/usr/local/lib/python3.10/site-packages/django/core/management/__init__.py", line 369, in execute
    settings.INSTALLED_APPS
  File "/usr/local/lib/python3.10/site-packages/django/conf/__init__.py", line 84, in __getattr__
    self._setup(name)
  File "/usr/local/lib/python3.10/site-packages/django/conf/__init__.py", line 71, in _setup
    self._wrapped = Settings(settings_module)
  File "/usr/local/lib/python3.10/site-packages/django/conf/__init__.py", line 179, in __init__
    mod = importlib.import_module(self.SETTINGS_MODULE)
  File "/usr/local/lib/python3.10/importlib/__init__.py", line 126, in import_module
    return _bootstrap._gcd_import(name[level:], package, level)
  File "<frozen importlib._bootstrap>", line 1050, in _gcd_import
  File "<frozen importlib._bootstrap>", line 1027, in _find_and_load
  File "<frozen importlib._bootstrap>", line 1006, in _find_and_load_unlocked
  File "<frozen importlib._bootstrap>", line 688, in _load_unlocked
  File "<frozen importlib._bootstrap_external>", line 879, in exec_module
  File "<frozen importlib._bootstrap_external>", line 1017, in get_code
  File "<frozen importlib._bootstrap_external>", line 947, in source_to_code
  File "<frozen importlib._bootstrap>", line 241, in _call_with_frames_removed
  File "/code/geospace/settings.py", line 28
    ALLOWED_HOSTS = [*]
                      ^
SyntaxError: invalid syntax
Traceback (most recent call last):
  File "/code/manage.py", line 22, in <module>
    main()
  File "/code/manage.py", line 18, in main
    execute_from_command_line(sys.argv)
  File "/usr/local/lib/python3.10/site-packages/django/core/management/__init__.py", line 425, in execute_from_command_line
    utility.execute()
  File "/usr/local/lib/python3.10/site-packages/django/core/management/__init__.py", line 369, in execute
    settings.INSTALLED_APPS
  File "/usr/local/lib/python3.10/site-packages/django/conf/__init__.py", line 84, in __getattr__
    self._setup(name)
  File "/usr/local/lib/python3.10/site-packages/django/conf/__init__.py", line 71, in _setup
    self._wrapped = Settings(settings_module)
  File "/usr/local/lib/python3.10/site-packages/django/conf/__init__.py", line 179, in __init__
    mod = importlib.import_module(self.SETTINGS_MODULE)
  File "/usr/local/lib/python3.10/importlib/__init__.py", line 126, in import_module
    return _bootstrap._gcd_import(name[level:], package, level)
  File "<frozen importlib._bootstrap>", line 1050, in _gcd_import
  File "<frozen importlib._bootstrap>", line 1027, in _find_and_load
  File "<frozen importlib._bootstrap>", line 1006, in _find_and_load_unlocked
  File "<frozen importlib._bootstrap>", line 688, in _load_unlocked
  File "<frozen importlib._bootstrap_external>", line 879, in exec_module
  File "<frozen importlib._bootstrap_external>", line 1017, in get_code
  File "<frozen importlib._bootstrap_external>", line 947, in source_to_code
  File "<frozen importlib._bootstrap>", line 241, in _call_with_frames_removed
  File "/code/geospace/settings.py", line 28
    ALLOWED_HOSTS = [*]
                      ^
SyntaxError: invalid syntax
Traceback (most recent call last):
  File "/code/manage.py", line 22, in <module>
    main()
  File "/code/manage.py", line 18, in main
    execute_from_command_line(sys.argv)
  File "/usr/local/lib/python3.10/site-packages/django/core/management/__init__.py", line 425, in execute_from_command_line
    utility.execute()
  File "/usr/local/lib/python3.10/site-packages/django/core/management/__init__.py", line 369, in execute
    settings.INSTALLED_APPS
  File "/usr/local/lib/python3.10/site-packages/django/conf/__init__.py", line 84, in __getattr__
    self._setup(name)
  File "/usr/local/lib/python3.10/site-packages/django/conf/__init__.py", line 71, in _setup
    self._wrapped = Settings(settings_module)
  File "/usr/local/lib/python3.10/site-packages/django/conf/__init__.py", line 179, in __init__
    mod = importlib.import_module(self.SETTINGS_MODULE)
  File "/usr/local/lib/python3.10/importlib/__init__.py", line 126, in import_module
    return _bootstrap._gcd_import(name[level:], package, level)
  File "<frozen importlib._bootstrap>", line 1050, in _gcd_import
  File "<frozen importlib._bootstrap>", line 1027, in _find_and_load
  File "<frozen importlib._bootstrap>", line 1006, in _find_and_load_unlocked
  File "<frozen importlib._bootstrap>", line 688, in _load_unlocked
  File "<frozen importlib._bootstrap_external>", line 879, in exec_module
  File "<frozen importlib._bootstrap_external>", line 1017, in get_code
  File "<frozen importlib._bootstrap_external>", line 947, in source_to_code
  File "<frozen importlib._bootstrap>", line 241, in _call_with_frames_removed
  File "/code/geospace/settings.py", line 28
    ALLOWED_HOSTS = [*]
                      ^
SyntaxError: invalid syntax
Watching for file changes with StatReloader
[03/Feb/2022 13:23:17] "GET / HTTP/1.1" 200 10697
[03/Feb/2022 13:23:18] "GET /static/admin/css/fonts.css HTTP/1.1" 200 423
[03/Feb/2022 13:23:18] "GET /static/admin/fonts/Roboto-Regular-webfont.woff HTTP/1.1" 200 85876
[03/Feb/2022 13:23:19] "GET /static/admin/fonts/Roboto-Bold-webfont.woff HTTP/1.1" 200 86184
[03/Feb/2022 13:23:19] "GET /static/admin/fonts/Roboto-Light-webfont.woff HTTP/1.1" 200 85692
Watching for file changes with StatReloader
[03/Feb/2022 13:24:59] "GET / HTTP/1.1" 200 10697
[03/Feb/2022 13:25:04] "GET /admin HTTP/1.1" 301 0
[03/Feb/2022 13:25:04] "GET /admin/ HTTP/1.1" 302 0
[03/Feb/2022 13:25:04] "GET /admin/login/?next=/admin/ HTTP/1.1" 200 2215
[03/Feb/2022 13:25:05] "GET /static/admin/css/nav_sidebar.css HTTP/1.1" 200 2616
[03/Feb/2022 13:25:05] "GET /static/admin/css/login.css HTTP/1.1" 200 954
[03/Feb/2022 13:25:05] "GET /static/admin/js/nav_sidebar.js HTTP/1.1" 200 3401
[03/Feb/2022 13:25:05] "GET /static/admin/css/base.css HTTP/1.1" 200 19513
[03/Feb/2022 13:25:05] "GET /static/admin/css/responsive.css HTTP/1.1" 200 18575
Internal Server Error: /admin/login/
Traceback (most recent call last):
  File "/usr/local/lib/python3.10/site-packages/django/db/backends/utils.py", line 85, in _execute
    return self.cursor.execute(sql, params)
  File "/usr/local/lib/python3.10/site-packages/django/db/backends/sqlite3/base.py", line 416, in execute
    return Database.Cursor.execute(self, query, params)
sqlite3.OperationalError: no such table: auth_user

The above exception was the direct cause of the following exception:

Traceback (most recent call last):
  File "/usr/local/lib/python3.10/site-packages/django/core/handlers/exception.py", line 47, in inner
    response = get_response(request)
  File "/usr/local/lib/python3.10/site-packages/django/core/handlers/base.py", line 181, in _get_response
    response = wrapped_callback(request, *callback_args, **callback_kwargs)
  File "/usr/local/lib/python3.10/site-packages/django/utils/decorators.py", line 43, in _wrapper
    return bound_method(*args, **kwargs)
  File "/usr/local/lib/python3.10/site-packages/django/views/decorators/cache.py", line 57, in _wrapped_view_func
    response = view_func(request, *args, **kwargs)
  File "/usr/local/lib/python3.10/site-packages/django/contrib/admin/sites.py", line 417, in login
    return LoginView.as_view(**defaults)(request)
  File "/usr/local/lib/python3.10/site-packages/django/views/generic/base.py", line 69, in view
    return self.dispatch(request, *args, **kwargs)
  File "/usr/local/lib/python3.10/site-packages/django/utils/decorators.py", line 43, in _wrapper
    return bound_method(*args, **kwargs)
  File "/usr/local/lib/python3.10/site-packages/django/views/decorators/debug.py", line 90, in sensitive_post_parameters_wrapper
    return view(request, *args, **kwargs)
  File "/usr/local/lib/python3.10/site-packages/django/utils/decorators.py", line 43, in _wrapper
    return bound_method(*args, **kwargs)
  File "/usr/local/lib/python3.10/site-packages/django/utils/decorators.py", line 130, in _wrapped_view
    response = view_func(request, *args, **kwargs)
  File "/usr/local/lib/python3.10/site-packages/django/utils/decorators.py", line 43, in _wrapper
    return bound_method(*args, **kwargs)
  File "/usr/local/lib/python3.10/site-packages/django/views/decorators/cache.py", line 57, in _wrapped_view_func
    response = view_func(request, *args, **kwargs)
  File "/usr/local/lib/python3.10/site-packages/django/contrib/auth/views.py", line 64, in dispatch
    return super().dispatch(request, *args, **kwargs)
  File "/usr/local/lib/python3.10/site-packages/django/views/generic/base.py", line 101, in dispatch
    return handler(request, *args, **kwargs)
  File "/usr/local/lib/python3.10/site-packages/django/views/generic/edit.py", line 143, in post
    if form.is_valid():
  File "/usr/local/lib/python3.10/site-packages/django/forms/forms.py", line 190, in is_valid
    return self.is_bound and not self.errors
  File "/usr/local/lib/python3.10/site-packages/django/forms/forms.py", line 185, in errors
    self.full_clean()
  File "/usr/local/lib/python3.10/site-packages/django/forms/forms.py", line 405, in full_clean
    self._clean_form()
  File "/usr/local/lib/python3.10/site-packages/django/forms/forms.py", line 426, in _clean_form
    cleaned_data = self.clean()
  File "/usr/local/lib/python3.10/site-packages/django/contrib/auth/forms.py", line 205, in clean
    self.user_cache = authenticate(self.request, username=username, password=password)
  File "/usr/local/lib/python3.10/site-packages/django/views/decorators/debug.py", line 42, in sensitive_variables_wrapper
    return func(*func_args, **func_kwargs)
  File "/usr/local/lib/python3.10/site-packages/django/contrib/auth/__init__.py", line 76, in authenticate
    user = backend.authenticate(request, **credentials)
  File "/usr/local/lib/python3.10/site-packages/django/contrib/auth/backends.py", line 42, in authenticate
    user = UserModel._default_manager.get_by_natural_key(username)
  File "/usr/local/lib/python3.10/site-packages/django/contrib/auth/base_user.py", line 44, in get_by_natural_key
    return self.get(**{self.model.USERNAME_FIELD: username})
  File "/usr/local/lib/python3.10/site-packages/django/db/models/manager.py", line 85, in manager_method
    return getattr(self.get_queryset(), name)(*args, **kwargs)
  File "/usr/local/lib/python3.10/site-packages/django/db/models/query.py", line 435, in get
    num = len(clone)
  File "/usr/local/lib/python3.10/site-packages/django/db/models/query.py", line 262, in __len__
    self._fetch_all()
  File "/usr/local/lib/python3.10/site-packages/django/db/models/query.py", line 1354, in _fetch_all
    self._result_cache = list(self._iterable_class(self))
  File "/usr/local/lib/python3.10/site-packages/django/db/models/query.py", line 51, in __iter__
    results = compiler.execute_sql(chunked_fetch=self.chunked_fetch, chunk_size=self.chunk_size)
  File "/usr/local/lib/python3.10/site-packages/django/db/models/sql/compiler.py", line 1202, in execute_sql
    cursor.execute(sql, params)
  File "/usr/local/lib/python3.10/site-packages/django/db/backends/utils.py", line 99, in execute
    return super().execute(sql, params)
  File "/usr/local/lib/python3.10/site-packages/django/db/backends/utils.py", line 67, in execute
    return self._execute_with_wrappers(sql, params, many=False, executor=self._execute)
  File "/usr/local/lib/python3.10/site-packages/django/db/backends/utils.py", line 76, in _execute_with_wrappers
    return executor(sql, params, many, context)
  File "/usr/local/lib/python3.10/site-packages/django/db/backends/utils.py", line 80, in _execute
    with self.db.wrap_database_errors:
  File "/usr/local/lib/python3.10/site-packages/django/db/utils.py", line 90, in __exit__
    raise dj_exc_value.with_traceback(traceback) from exc_value
  File "/usr/local/lib/python3.10/site-packages/django/db/backends/utils.py", line 85, in _execute
    return self.cursor.execute(sql, params)
  File "/usr/local/lib/python3.10/site-packages/django/db/backends/sqlite3/base.py", line 416, in execute
    return Database.Cursor.execute(self, query, params)
django.db.utils.OperationalError: no such table: auth_user
[03/Feb/2022 13:25:12] "POST /admin/login/?next=/admin/ HTTP/1.1" 500 230493
[03/Feb/2022 13:25:14] "GET /admin/login/?next=/admin/ HTTP/1.1" 200 2215
[03/Feb/2022 13:28:45] "POST /admin/login/?next=/admin/ HTTP/1.1" 200 2378
[03/Feb/2022 13:28:46] "GET /static/admin/css/fonts.css HTTP/1.1" 304 0
[03/Feb/2022 13:28:57] "POST /admin/login/?next=/admin/ HTTP/1.1" 302 0
[03/Feb/2022 13:28:57] "GET /admin/ HTTP/1.1" 200 3329
[03/Feb/2022 13:28:57] "GET /static/admin/css/dashboard.css HTTP/1.1" 200 380
[03/Feb/2022 13:28:58] "GET /static/admin/img/icon-changelink.svg HTTP/1.1" 200 380
[03/Feb/2022 13:28:58] "GET /static/admin/img/icon-addlink.svg HTTP/1.1" 200 331
[03/Feb/2022 13:29:03] "GET /admin/logout/ HTTP/1.1" 200 1530
[03/Feb/2022 13:29:03] "GET /static/admin/css/base.css HTTP/1.1" 304 0
[03/Feb/2022 13:29:03] "GET /static/admin/js/nav_sidebar.js HTTP/1.1" 304 0
[03/Feb/2022 13:29:03] "GET /static/admin/css/nav_sidebar.css HTTP/1.1" 304 0
[03/Feb/2022 13:29:03] "GET /static/admin/css/responsive.css HTTP/1.1" 304 0
[03/Feb/2022 13:29:05] "GET /admin/ HTTP/1.1" 302 0
[03/Feb/2022 13:29:06] "GET /admin/login/?next=/admin/ HTTP/1.1" 200 2215
[03/Feb/2022 13:29:06] "GET /static/admin/css/login.css HTTP/1.1" 304 0
Watching for file changes with StatReloader
[03/Feb/2022 13:30:26] "GET /admin/login/?next=/admin/ HTTP/1.1" 200 2215
[03/Feb/2022 13:30:26] "GET /static/admin/css/login.css HTTP/1.1" 304 0
[03/Feb/2022 13:30:26] "GET /static/admin/js/nav_sidebar.js HTTP/1.1" 304 0
[03/Feb/2022 13:30:30] "POST /admin/login/?next=/admin/ HTTP/1.1" 302 0
[03/Feb/2022 13:30:31] "GET /admin/ HTTP/1.1" 200 3329
[03/Feb/2022 13:30:33] "GET /admin/logout/ HTTP/1.1" 200 1530
